<sdf version='1.10'>
    <world name='lift_drag'>

        <plugin name='gz::sim::systems::Physics' filename='gz-sim-physics-system'/>
        <plugin name='gz::sim::systems::UserCommands' filename='gz-sim-user-commands-system'/>
        <plugin name='gz::sim::systems::SceneBroadcaster' filename='gz-sim-scene-broadcaster-system'/>
        <plugin name='gz::sim::systems::Sensors' filename='gz-sim-sensors-system'/>
        <plugin name="gz::sim::systems::Imu" filename="gz-sim-imu-system"></plugin>
        <gravity>0 0 -9.8000000000000007</gravity>
        <magnetic_field>5.5644999999999998e-06 2.2875799999999999e-05 -4.2388400000000002e-05</magnetic_field>
        <atmosphere type='adiabatic'/>

        <physics type='ode'>
            <max_step_size>0.0001</max_step_size>
            <real_time_factor>1</real_time_factor>
            <real_time_update_rate>10000</real_time_update_rate>
        </physics>
        
        <scene>
            <ambient>0.4 0.4 0.4 1</ambient>
            <background>0.7 0.7 0.7 1</background>
            <shadows>true</shadows>
        </scene>

        <model name='ground'>
            <static>true</static>
            <link name='link'>
                <collision name='collision'>
                    <geometry>
                    <plane>
                        <normal>0 0 1</normal>
                        <size>100000 100</size>
                    </plane>
                    </geometry>
                </collision>
                <visual name='visual'>
                    <geometry>
                    <plane>
                        <normal>0 0 1</normal>
                        <size>100000 100</size>
                    </plane>
                    </geometry>
                    <material>
                        <ambient>0.1 0.1 0.1 1</ambient>
                        <diffuse>0.1 0.1 0.1 1</diffuse>
                        <specular>0.1 0.1 0.1 1</specular>
                    </material>
                </visual>
                <pose>0 0 0 0 0 0</pose>
            </link>
            <pose>0 0 0 0 0 0</pose>
            <self_collide>false</self_collide>
        </model>


        <model name='plane'>
            <pose>0 0 0.5 0 0 0</pose>
            <static>false</static>


            <link name='body'>
                <pose>-0.2 0 0 0 1.57 0</pose>
                <inertial>
                    <pose>0 0 0 0 0 0</pose>
                    <inertia>
                    <ixx>5</ixx>
                    <ixy>0</ixy>
                    <ixz>0</ixz>
                    <iyy>10</iyy>
                    <iyz>0</iyz>
                    <izz>10</izz>
                    </inertia>
                    <mass>5</mass>
                </inertial>
                <collision name='collision'>
                    <pose>0 0 0 0 0 0</pose>
                    <geometry>
                        <cylinder>
                            <radius>0.1</radius>
                            <length>0.6</length>
                        </cylinder>
                    </geometry>
                </collision>
                <visual name='visual'>
                    <pose>0 0 0 0 0 0</pose>
                    <geometry>
                        <cylinder>
                            <radius>0.1</radius>
                            <length>0.6</length>
                        </cylinder>
                    </geometry>
                    <material>
                        <ambient>0.8 0.8 0.8 1</ambient>
                        <diffuse>0.8 0.8 0.8 1</diffuse>
                    </material>
                </visual>
                <sensor name="imu" type="imu">
                    <pose>0 0 0 0 -1.57 0</pose>
                    <always_on>1</always_on>
                    <update_rate>100</update_rate>
                    <visualize>true</visualize>
                    <topic>/pos/imu</topic>
                </sensor>
            </link>

            <link name='left_propeller'>
                <pose>0.4 0.1 0 0 -1.0 0</pose>
                <inertial>
                    <pose>0 0 0 0 0 0</pose>
                    <inertia>
                    <ixx>0.000001</ixx>
                    <ixy>0</ixy>
                    <ixz>0</ixz>
                    <iyy>0.000001</iyy>
                    <iyz>0</iyz>
                    <izz>0.000001</izz>
                    </inertia>
                    <mass>0.000001</mass>
                </inertial>
                <visual name='visual'>
                    <pose>0 0 0 0 0 0</pose>
                    <geometry>
                        <box>
                            <size>0.03 0.25 0.01</size>
                        </box>
                    </geometry>
                    <material>
                        <ambient>0 0 0 1</ambient>
                        <diffuse>0 0 0 1</diffuse>
                    </material>
                </visual>
            </link>
            <joint name='left_propeller_joint' type='revolute'>
                <parent>body</parent>
                <child>left_propeller</child>
                <pose relative_to='body'> 0 0 0 0 0 0 </pose> 
                <axis>
                    <xyz>0 0 1</xyz>
                </axis>
            </joint>
            <plugin
                filename="gz-sim-joint-controller-system"
                name="gz::sim::systems::JointController">
                <joint_name>left_propeller_joint</joint_name>
                <initial_velocity>0</initial_velocity>
                <topic>/cmd/thruster</topic>
            </plugin>
            <plugin name="gz::sim::systems::LiftDrag"
                filename="gz-sim-lift-drag-system">
                <a0>0.0</a0>
                <alpha_stall>0.35</alpha_stall>
                <cla>6.1</cla>
                <cda>0.18</cda>
                <cla_stall>-5.0</cla_stall>
                <cda_stall>1.1</cda_stall>
                <area>0.0075</area>
                <air_density>1.2041</air_density>
                <cp>0 0 0</cp>
                <forward>1 0 0</forward>
                <upward>0 0 1</upward>
                <link_name>left_propeller</link_name>
            </plugin>

            <link name='right_propeller'>
                <pose>0.4 -0.1 0 0 1.0 0</pose>
                <inertial>
                    <pose>0 0 0 0 0 0</pose>
                    <inertia>
                    <ixx>0.000001</ixx>
                    <ixy>0</ixy>
                    <ixz>0</ixz>
                    <iyy>0.000001</iyy>
                    <iyz>0</iyz>
                    <izz>0.000001</izz>
                    </inertia>
                    <mass>0.000001</mass>
                </inertial>
                <visual name='visual'>
                    <pose>0 0 0 0 0 0</pose>
                    <geometry>
                        <box>
                            <size>0.03 0.25 0.01</size>
                        </box>
                    </geometry>
                    <material>
                        <ambient>0 0 0 1</ambient>
                        <diffuse>0 0 0 1</diffuse>
                    </material>
                </visual>
            </link>
            <joint name='right_propeller_joint' type='fixed'>
                <parent>left_propeller</parent>
                <child>right_propeller</child>
            </joint>
            <plugin name="gz::sim::systems::LiftDrag"
                filename="gz-sim-lift-drag-system">
                <a0>0.0</a0>
                <alpha_stall>0.35</alpha_stall>
                <cla>6.1</cla>
                <cda>0.18</cda>
                <cla_stall>-5.0</cla_stall>
                <cda_stall>1.1</cda_stall>
                <area>0.0075</area>
                <air_density>1.2041</air_density>
                <cp>0 0 0</cp>
                <forward>1 0 0</forward>
                <upward>0 0 1</upward>
                <link_name>right_propeller</link_name>
            </plugin>

            

            <link name='left_wing'>
                <pose>0 1 0.2 0.14 -0.035 0</pose>
                <inertial>
                    <pose>0 0 0 0 0 0</pose>
                    <mass>0.5</mass>
                </inertial>
                <collision name='collision'>
                    <pose>0 0 0 0 0 0</pose>
                    <geometry>
                        <box>
                            <size>0.3 1.5 0.01</size>
                        </box>
                    </geometry>
                </collision>
                <visual name='visual'>
                    <pose>0 0 0 0 0 0</pose>
                    <geometry>
                        <box>
                            <size>0.3 1.5 0.01</size>
                        </box>
                    </geometry>
                    <material>
                        <ambient>0.8 0.8 0.8 1</ambient>
                        <diffuse>0.8 0.8 0.8 1</diffuse>
                    </material>
                </visual>
            </link>
            <joint name='left_wing_joint' type='fixed'>
                <parent>body</parent>
                <child>left_wing</child>
            </joint>
            <plugin name="gz::sim::systems::LiftDrag"
                filename="gz-sim-lift-drag-system">
                <a0>0.0</a0>
                <alpha_stall>0.35</alpha_stall>
                <cla>6.1</cla>
                <cda>0.18</cda>
                <cla_stall>-5.0</cla_stall>
                <cda_stall>1.1</cda_stall>
                <area>0.45</area>
                <air_density>1.2041</air_density>
                <cp>0 0 0</cp>
                <forward>0 1 0</forward>
                <upward>0 0 1</upward>
                <link_name>left_wing</link_name>
            </plugin>

            <link name='left_flap'>
                <pose relative_to='left_wing'>-0.25 0 0 0 0 0</pose>
                <inertial>
                    <pose>0 0 0 0 0 0</pose>
                    <inertia>
                    <ixx>0.000001</ixx>
                    <ixy>0</ixy>
                    <ixz>0</ixz>
                    <iyy>0.000001</iyy>
                    <iyz>0</iyz>
                    <izz>0.000001</izz>
                    </inertia>
                    <mass>0.000001</mass>
                </inertial>
                <collision name='collision'>
                    <pose>0 0 0 0 0 0</pose>
                    <geometry>
                        <box>
                            <size>0.2 1.5 0.01</size>
                        </box>
                    </geometry>
                </collision>
                <visual name='visual'>
                    <pose>0 0 0 0 0 0</pose>
                    <geometry>
                        <box>
                            <size>0.2 1.5 0.01</size>
                        </box>
                    </geometry>
                    <material>
                        <ambient>0 0 0 1</ambient>
                        <diffuse>0 0 0 1</diffuse>
                    </material>
                </visual>
            </link>
            <joint name='left_flap_joint' type='revolute'>
                <parent>left_wing</parent>
                <child>left_flap</child>
                <pose relative_to='left_flap'> 0.1 0 0 0 0 0 </pose> 
                <axis>
                    <xyz>0 -1 0</xyz>
                    <limit>
                        <lower> -0.5 </lower>
                        <upper> 0.5 </upper>
                        <effort>1000000</effort>
                    </limit>
                </axis>
            </joint>
            <plugin
                filename="gz-sim-joint-position-controller-system"
                name="gz::sim::systems::JointPositionController">
                <joint_name>left_flap_joint</joint_name>
                <initial_position>0</initial_position>
                <use_velocity_commands>true</use_velocity_commands>
                <topic>/cmd/left_flap</topic>
            </plugin>
            <plugin name="gz::sim::systems::LiftDrag"
                filename="gz-sim-lift-drag-system">
                <a0>0.0</a0>
                <alpha_stall>0.35</alpha_stall>
                <cla>6.1</cla>
                <cda>0.18</cda>
                <cla_stall>-5.0</cla_stall>
                <cda_stall>1.1</cda_stall>
                <area>0.3</area>
                <air_density>1.2041</air_density>
                <cp>0 0 0</cp>
                <forward>1 0 0</forward>
                <upward>0 0 1</upward>
                <link_name>left_flap</link_name>
            </plugin>

            <link name='right_wing'>
                <pose>0 -1 0.2 -0.14 -0.035 0</pose>
                <inertial>
                    <pose>0 0 0 0 0 0</pose>
                    <mass>0.5</mass>
                </inertial>
                <collision name='collision'>
                    <pose>0 0 0 0 0 0</pose>
                    <geometry>
                        <box>
                            <size>0.3 1.5 0.01</size>
                        </box>
                    </geometry>
                </collision>
                <visual name='visual'>
                    <pose>0 0 0 0 0 0</pose>
                    <geometry>
                        <box>
                            <size>0.3 1.5 0.01</size>
                        </box>
                    </geometry>
                    <material>
                        <ambient>0.8 0.8 0.8 1</ambient>
                        <diffuse>0.8 0.8 0.8 1</diffuse>
                    </material>
                </visual>
            </link>
            <joint name='right_wing_joint' type='fixed'>
                <parent>body</parent>
                <child>right_wing</child>
            </joint>
            <plugin name="gz::sim::systems::LiftDrag"
                filename="gz-sim-lift-drag-system">
                <a0>0.0</a0>
                <alpha_stall>0.35</alpha_stall>
                <cla>6.1</cla>
                <cda>0.18</cda>
                <cla_stall>-5.0</cla_stall>
                <cda_stall>1.1</cda_stall>
                <area>0.45</area>
                <air_density>1.2041</air_density>
                <cp>0 0 0</cp>
                <forward>1 0 0</forward>
                <upward>0 0 1</upward>
                <link_name>right_wing</link_name>
            </plugin>

            <link name='right_flap'>
                <pose relative_to='right_wing'>-0.25 0 0 0 0 0</pose>
                <inertial>
                    <pose>0 0 0 0 0 0</pose>
                    <inertia>
                    <ixx>0.000001</ixx>
                    <ixy>0</ixy>
                    <ixz>0</ixz>
                    <iyy>0.000001</iyy>
                    <iyz>0</iyz>
                    <izz>0.000001</izz>
                    </inertia>
                    <mass>0.000001</mass>
                </inertial>
                <collision name='collision'>
                    <pose>0 0 0 0 0 0</pose>
                    <geometry>
                        <box>
                            <size>0.2 1.5 0.01</size>
                        </box>
                    </geometry>
                </collision>
                <visual name='visual'>
                    <pose>0 0 0 0 0 0</pose>
                    <geometry>
                        <box>
                            <size>0.2 1.5 0.01</size>
                        </box>
                    </geometry>
                    <material>
                        <ambient>0 0 0 1</ambient>
                        <diffuse>0 0 0 1</diffuse>
                    </material>
                </visual>
            </link>
            <joint name='right_flap_joint' type='revolute'>
                <parent>right_wing</parent>
                <child>right_flap</child>
                <pose relative_to='right_flap'> 0.1 0 0 0 0 0 </pose> 
                <axis>
                    <xyz>0 -1 0</xyz>
                    <limit>
                        <lower> -0.5 </lower>
                        <upper> 0.5 </upper>
                        <effort>1000000</effort>
                    </limit>
                </axis>
            </joint>
            <plugin
                filename="gz-sim-joint-position-controller-system"
                name="gz::sim::systems::JointPositionController">
                <joint_name>right_flap_joint</joint_name>
                <initial_position>0</initial_position>
                <use_velocity_commands>true</use_velocity_commands>
                <topic>/cmd/right_flap</topic>
            </plugin>
            <plugin name="gz::sim::systems::LiftDrag"
                filename="gz-sim-lift-drag-system">
                <a0>0.0</a0>
                <alpha_stall>0.35</alpha_stall>
                <cla>6.1</cla>
                <cda>0.18</cda>
                <cla_stall>-5.0</cla_stall>
                <cda_stall>1.1</cda_stall>
                <area>0.3</area>
                <air_density>1.2041</air_density>
                <cp>0 0 0</cp>
                <forward>1 0 0</forward>
                <upward>0 0 1</upward>
                <link_name>right_flap</link_name>
            </plugin>

            <link name='tail'>
                <pose>-1.3 0 0.1 0 1.57 0</pose>
                <inertial>
                    <pose>0 0 0 0 0 0</pose>
                    <inertia>
                    <ixx>0.5</ixx>
                    <ixy>0</ixy>
                    <ixz>0</ixz>
                    <iyy>1</iyy>
                    <iyz>0</iyz>
                    <izz>1</izz>
                    </inertia>
                    <mass>0.2</mass>
                </inertial>
                <collision name='collision'>
                    <pose>0 0 0 0 0 0</pose>
                    <geometry>
                        <cylinder>
                            <radius>0.05</radius>
                            <length>0.3</length>
                        </cylinder>
                    </geometry>
                </collision>
                <visual name='visual'>
                    <pose>0 0 0 0 0 0</pose>
                    <geometry>
                        <cylinder>
                            <radius>0.05</radius>
                            <length>0.3</length>
                        </cylinder>
                    </geometry>
                    <material>
                        <ambient>0.8 0.8 0.8 1</ambient>
                        <diffuse>0.8 0.8 0.8 1</diffuse>
                    </material>
                </visual>
            </link>
            <joint name='tail_joint' type='fixed'>
                <parent>body</parent>
                <child>tail</child>
            </joint>

            <link name='left_elevator'>
                <pose>-1.3 0.35 0.1 0.14 -0.035 0</pose>
                <inertial>
                    <pose>0 0 0 0 0 0</pose>
                    <mass>0.2</mass>
                </inertial>
                <collision name='collision'>
                    <pose>0 0 0 0 0 0</pose>
                    <geometry>
                        <box>
                            <size>0.3 0.5 0.01</size>
                        </box>
                    </geometry>
                </collision>
                <visual name='visual'>
                    <pose>0 0 0 0 0 0</pose>
                    <geometry>
                        <box>
                            <size>0.3 0.5 0.01</size>
                        </box>
                    </geometry>
                    <material>
                        <ambient>0.8 0.8 0.8 1</ambient>
                        <diffuse>0.8 0.8 0.8 1</diffuse>
                    </material>
                </visual>
            </link>
            <joint name='left_elevator_joint' type='fixed'>
                <parent>body</parent>
                <child>left_elevator</child>
            </joint>
            <plugin name="gz::sim::systems::LiftDrag"
                filename="gz-sim-lift-drag-system">
                <a0>0.0</a0>
                <alpha_stall>0.35</alpha_stall>
                <cla>6.1</cla>
                <cda>0.18</cda>
                <cla_stall>-5.0</cla_stall>
                <cda_stall>1.1</cda_stall>
                <area>0.15</area>
                <air_density>1.2041</air_density>
                <cp>0 0 0</cp>
                <forward>1 0 0</forward>
                <upward>0 0 1</upward>
                <link_name>left_elevator</link_name>
            </plugin>

            <link name='left_elevator_flap'>
                <pose relative_to='left_elevator'>-0.25 0 0 0 0 0</pose>
                <inertial>
                    <pose>0 0 0 0 0 0</pose>
                    <inertia>
                    <ixx>0.000001</ixx>
                    <ixy>0</ixy>
                    <ixz>0</ixz>
                    <iyy>0.000001</iyy>
                    <iyz>0</iyz>
                    <izz>0.000001</izz>
                    </inertia>
                    <mass>0.000001</mass>
                </inertial>
                <collision name='collision'>
                    <pose>0 0 0 0 0 0</pose>
                    <geometry>
                        <box>
                            <size>0.2 0.5 0.01</size>
                        </box>
                    </geometry>
                </collision>
                <visual name='visual'>
                    <pose>0 0 0 0 0 0</pose>
                    <geometry>
                        <box>
                            <size>0.2 0.5 0.01</size>
                        </box>
                    </geometry>
                    <material>
                        <ambient>0 0 0 1</ambient>
                        <diffuse>0 0 0 1</diffuse>
                    </material>
                </visual>
            </link>
            <joint name='left_elevator_flap_joint' type='revolute'>
                <parent>left_elevator</parent>
                <child>left_elevator_flap</child>
                <pose relative_to='left_elevator_flap'> 0.1 0 0 0 0 0 </pose> 
                <axis>
                    <xyz>0 -1 0</xyz>
                    <limit>
                        <lower> -0.5 </lower>
                        <upper> 0.5 </upper>
                        <effort>1000000</effort>
                    </limit>
                </axis>
            </joint>
            <plugin
                filename="gz-sim-joint-position-controller-system"
                name="gz::sim::systems::JointPositionController">
                <joint_name>left_elevator_flap_joint</joint_name>
                <initial_position>0</initial_position>
                <use_velocity_commands>true</use_velocity_commands>
                <topic>/cmd/elevators</topic>
            </plugin>
            <plugin name="gz::sim::systems::LiftDrag"
                filename="gz-sim-lift-drag-system">
                <a0>0.0</a0>
                <alpha_stall>0.35</alpha_stall>
                <cla>6.1</cla>
                <cda>0.18</cda>
                <cla_stall>-5.0</cla_stall>
                <cda_stall>1.1</cda_stall>
                <area>0.1</area>
                <air_density>1.2041</air_density>
                <cp>0 0 0</cp>
                <forward>1 0 0</forward>
                <upward>0 0 1</upward>
                <link_name>left_elevator_flap</link_name>
            </plugin>

            <link name='right_elevator'>
                <pose>-1.3 -0.35 0.1 -0.14 -0.035 0</pose>
                <inertial>
                    <pose>0 0 0 0 0 0</pose>
                    <mass>0.2</mass>
                </inertial>
                <collision name='collision'>
                    <pose>0 0 0 0 0 0</pose>
                    <geometry>
                        <box>
                            <size>0.3 0.5 0.01</size>
                        </box>
                    </geometry>
                </collision>
                <visual name='visual'>
                    <pose>0 0 0 0 0 0</pose>
                    <geometry>
                        <box>
                            <size>0.3 0.5 0.01</size>
                        </box>
                    </geometry>
                    <material>
                        <ambient>0.8 0.8 0.8 1</ambient>
                        <diffuse>0.8 0.8 0.8 1</diffuse>
                    </material>
                </visual>
            </link>
            <joint name='right_elevator_joint' type='fixed'>
                <parent>body</parent>
                <child>right_elevator</child>
            </joint>
            <plugin name="gz::sim::systems::LiftDrag"
                filename="gz-sim-lift-drag-system">
                <a0>0.0</a0>
                <alpha_stall>0.35</alpha_stall>
                <cla>6.1</cla>
                <cda>0.18</cda>
                <cla_stall>-5.0</cla_stall>
                <cda_stall>1.1</cda_stall>
                <area>0.15</area>
                <air_density>1.2041</air_density>
                <cp>0 0 0</cp>
                <forward>1 0 0</forward>
                <upward>0 0 1</upward>
                <link_name>right_elevator</link_name>
            </plugin>

            <link name='right_elevator_flap'>
                <pose relative_to='right_elevator'>-0.25 0 0 0 0 0</pose>
                <inertial>
                    <pose>0 0 0 0 0 0</pose>
                    <inertia>
                    <ixx>0.000001</ixx>
                    <ixy>0</ixy>
                    <ixz>0</ixz>
                    <iyy>0.000001</iyy>
                    <iyz>0</iyz>
                    <izz>0.000001</izz>
                    </inertia>
                    <mass>0.000001</mass>
                </inertial>
                <collision name='collision'>
                    <pose>0 0 0 0 0 0</pose>
                    <geometry>
                        <box>
                            <size>0.2 0.5 0.01</size>
                        </box>
                    </geometry>
                </collision>
                <visual name='visual'>
                    <pose>0 0 0 0 0 0</pose>
                    <geometry>
                        <box>
                            <size>0.2 0.5 0.01</size>
                        </box>
                    </geometry>
                    <material>
                        <ambient>0 0 0 1</ambient>
                        <diffuse>0 0 0 1</diffuse>
                    </material>
                </visual>
            </link>
            <joint name='right_elevator_flap_joint' type='revolute'>
                <parent>right_elevator</parent>
                <child>right_elevator_flap</child>
                <pose relative_to='right_elevator_flap'> 0.1 0 0 0 0 0 </pose> 
                <axis>
                    <xyz>0 -1 0</xyz>
                    <limit>
                        <lower> -0.5 </lower>
                        <upper> 0.5 </upper>
                        <effort>1000000</effort>
                    </limit>
                </axis>
            </joint>
            <plugin
                filename="gz-sim-joint-position-controller-system"
                name="gz::sim::systems::JointPositionController">
                <joint_name>right_elevator_flap_joint</joint_name>
                <initial_position>0</initial_position>
                <use_velocity_commands>true</use_velocity_commands>
                <topic>/cmd/elevators</topic>
            </plugin>
            <plugin name="gz::sim::systems::LiftDrag"
                filename="gz-sim-lift-drag-system">
                <a0>0.0</a0>
                <alpha_stall>0.35</alpha_stall>
                <cla>6.1</cla>
                <cda>0.18</cda>
                <cla_stall>-5.0</cla_stall>
                <cda_stall>1.1</cda_stall>
                <area>0.1</area>
                <air_density>1.2041</air_density>
                <cp>0 0 0</cp>
                <forward>1 0 0</forward>
                <upward>0 0 1</upward>
                <link_name>right_elevator_flap</link_name>
            </plugin>

            <link name='left_wheel'>
                <pose>0.2 0.3 -0.3 1.57 0 0</pose>
                <inertial>
                    <pose>0 0 0 0 0 0</pose>
                    <mass>0.02</mass>
                </inertial>
                <collision name='collision'>
                    <pose>0 0 0 0 0 0</pose>
                    <geometry>
                        <cylinder>
                            <radius>0.08</radius>
                            <length>0.02</length>
                        </cylinder>
                    </geometry>
                </collision>
                <visual name='visual'>
                    <pose>0 0 0 0 0 0</pose>
                    <geometry>
                        <cylinder>
                            <radius>0.08</radius>
                            <length>0.02</length>
                        </cylinder>
                    </geometry>
                    <material>
                        <ambient>0.0 0.0 0.0 1</ambient>
                        <diffuse>0.0 0.0 0.0 1</diffuse>
                    </material>
                </visual>
            </link>
            <joint name='left_wheel_joint' type='revolute'>
                <parent>body</parent>
                <child>left_wheel</child>
                <pose relative_to='left_wheel'> 0 0 0 0 0 0 </pose> 
                <axis>
                    <xyz>0 0 1</xyz>
                    <limit>
                        <lower>-100000</lower>
                        <upper>100000</upper>
                    </limit>
                </axis>
            </joint>

            <link name='right_wheel'>
                <pose>0.2 -0.3 -0.3 1.57 0 0</pose>
                <inertial>
                    <pose>0 0 0 0 0 0</pose>
                    <mass>0.02</mass>
                </inertial>
                <collision name='collision'>
                    <pose>0 0 0 0 0 0</pose>
                    <geometry>
                        <cylinder>
                            <radius>0.08</radius>
                            <length>0.02</length>
                        </cylinder>
                    </geometry>
                </collision>
                <visual name='visual'>
                    <pose>0 0 0 0 0 0</pose>
                    <geometry>
                        <cylinder>
                            <radius>0.08</radius>
                            <length>0.02</length>
                        </cylinder>
                    </geometry>
                    <material>
                        <ambient>0.0 0.0 0.0 1</ambient>
                        <diffuse>0.0 0.0 0.0 1</diffuse>
                    </material>
                </visual>
            </link>
            <joint name='right_wheel_joint' type='revolute'>
                <parent>body</parent>
                <child>right_wheel</child>
                <pose relative_to='right_wheel'> 0 0 0 0 0 0 </pose> 
                <axis>
                    <xyz>0 0 1</xyz>
                    <limit>
                        <lower>-100000</lower>
                        <upper>100000</upper>
                    </limit>
                </axis>
            </joint>

            <link name='back_wheel'>
                <pose>-1.3 0 -0.1 1.57 0 0</pose>
                <inertial>
                    <pose>0 0 0 0 0 0</pose>
                    <mass>0.02</mass>
                </inertial>
                <collision name='collision'>
                    <pose>0 0 0 0 0 0</pose>
                    <geometry>
                        <cylinder>
                            <radius>0.08</radius>
                            <length>0.02</length>
                        </cylinder>
                    </geometry>
                </collision>
                <visual name='visual'>
                    <pose>0 0 0 0 0 0</pose>
                    <geometry>
                        <cylinder>
                            <radius>0.08</radius>
                            <length>0.02</length>
                        </cylinder>
                    </geometry>
                    <material>
                        <ambient>0.0 0.0 0.0 1</ambient>
                        <diffuse>0.0 0.0 0.0 1</diffuse>
                    </material>
                </visual>
            </link>
            <joint name='back_wheel_joint' type='revolute'>
                <parent>body</parent>
                <child>back_wheel</child>
                <pose relative_to='back_wheel'> 0 0 0 0 0 0 </pose> 
                <axis>
                    <xyz>0 0 1</xyz>
                    <limit>
                        <lower>-100000</lower>
                        <upper>100000</upper>
                    </limit>
                </axis>
            </joint>

        </model>

        



        <light name='sun' type='directional'>
            <pose>0 0 10 0 0 0</pose>
            <cast_shadows>true</cast_shadows>
            <intensity>1</intensity>
            <direction>-0.5 0.10000000000000001 -0.90000000000000002</direction>
            <diffuse>1 1 1 1</diffuse>
            <specular>0.5 0.5 0.5 1</specular>
            <attenuation>
            <range>1000</range>
            <linear>0.0099999997764825821</linear>
            <constant>0.89999997615814209</constant>
            <quadratic>0.0010000000474974513</quadratic>
            </attenuation>
            <spot>
            <inner_angle>0</inner_angle>
            <outer_angle>0</outer_angle>
            <falloff>0</falloff>
            </spot>
        </light>
    </world>
</sdf>
